2017-01-16 15:11:20,909 [Dummy-1:140658016102144] [django.db.backends:89] [utils:execute] [DEBUG]- (0.001) SET SQL_AUTO_IS_NULL = 0; args=None
2017-01-16 15:11:20,941 [Dummy-1:140658016102144] [django.db.backends:89] [utils:execute] [DEBUG]- (0.000) SET SQL_AUTO_IS_NULL = 0; args=None
2017-01-16 15:11:20,951 [Dummy-1:140658016102144] [django.db.backends:89] [utils:execute] [DEBUG]- (0.010) SHOW FULL TABLES; args=None
2017-01-16 15:11:20,954 [Dummy-1:140658016102144] [django.db.backends:89] [utils:execute] [DEBUG]- (0.001) SELECT `django_migrations`.`app`, `django_migrations`.`name` FROM `django_migrations`; args=()
2017-01-16 15:26:55,560 [Dummy-1:140201134483200] [django.db.backends:89] [utils:execute] [DEBUG]- (0.000) SET SQL_AUTO_IS_NULL = 0; args=None
2017-01-16 15:26:55,595 [Dummy-1:140201134483200] [django.db.backends:89] [utils:execute] [DEBUG]- (0.000) SET SQL_AUTO_IS_NULL = 0; args=None
2017-01-16 15:26:55,598 [Dummy-1:140201134483200] [django.db.backends:89] [utils:execute] [DEBUG]- (0.001) SHOW FULL TABLES; args=None
2017-01-16 15:26:55,601 [Dummy-1:140201134483200] [django.db.backends:89] [utils:execute] [DEBUG]- (0.001) SELECT `django_migrations`.`app`, `django_migrations`.`name` FROM `django_migrations`; args=()
2017-01-16 15:31:39,279 [Thread-4:140201122608896] [django.template:927] [base:_resolve_lookup] [DEBUG]- Exception while resolving variable 'global_test' in template 'index.html'.
Traceback (most recent call last):
  File "/usr/local/lib/python2.7/dist-packages/Django-1.9.7-py2.7.egg/django/template/base.py", line 905, in _resolve_lookup
    (bit, current))  # missing attribute
VariableDoesNotExist: Failed lookup for key [global_test] in u"[{'False': False, 'None': None, 'True': True}, {u'csrf_token': <SimpleLazyObject: <function _get_val at 0x7f831d151c80>>, 'site_name': 'django learn', 'user': <SimpleLazyObject: <function <lambda> at 0x7f831d9b7c08>>, 'perms': <django.contrib.auth.context_processors.PermWrapper object at 0x7f831d1585d0>, 'DEFAULT_MESSAGE_LEVELS': {'DEBUG': 10, 'INFO': 20, 'WARNING': 30, 'SUCCESS': 25, 'ERROR': 40}, 'messages': <django.contrib.messages.storage.fallback.FallbackStorage object at 0x7f831d9ae350>, 'global_message': 'This is a global test message', u'request': <WSGIRequest: GET '/index/'>, 'site_url': 'http://www.newbieol.com'}, {}]"
2017-01-16 15:34:36,553 [Thread-6:140201122608896] [django.template:927] [base:_resolve_lookup] [DEBUG]- Exception while resolving variable 'global_test' in template 'index.html'.
Traceback (most recent call last):
  File "/usr/local/lib/python2.7/dist-packages/Django-1.9.7-py2.7.egg/django/template/base.py", line 905, in _resolve_lookup
    (bit, current))  # missing attribute
VariableDoesNotExist: Failed lookup for key [global_test] in u"[{'False': False, 'None': None, 'True': True}, {u'csrf_token': <SimpleLazyObject: <function _get_val at 0x7f831d9b79b0>>, 'site_name': 'django learn', 'user': <SimpleLazyObject: <function <lambda> at 0x7f831d9b78c0>>, 'perms': <django.contrib.auth.context_processors.PermWrapper object at 0x7f831d159ad0>, 'DEFAULT_MESSAGE_LEVELS': {'DEBUG': 10, 'INFO': 20, 'WARNING': 30, 'SUCCESS': 25, 'ERROR': 40}, 'messages': <django.contrib.messages.storage.fallback.FallbackStorage object at 0x7f831d1598d0>, 'global_message': 'This is a global test message', u'request': <WSGIRequest: GET '/index/'>, 'site_url': 'http://www.newbieol.com'}, {}]"
2017-01-16 15:37:24,730 [Thread-8:140201105037056] [django.template:927] [base:_resolve_lookup] [DEBUG]- Exception while resolving variable 'global_test' in template 'index.html'.
Traceback (most recent call last):
  File "/usr/local/lib/python2.7/dist-packages/Django-1.9.7-py2.7.egg/django/template/base.py", line 905, in _resolve_lookup
    (bit, current))  # missing attribute
VariableDoesNotExist: Failed lookup for key [global_test] in u"[{'False': False, 'None': None, 'True': True}, {u'csrf_token': <SimpleLazyObject: <function _get_val at 0x7f831d9b7398>>, 'site_name': 'django learn', 'user': <SimpleLazyObject: <function <lambda> at 0x7f831d9b7500>>, 'perms': <django.contrib.auth.context_processors.PermWrapper object at 0x7f831d159c90>, 'DEFAULT_MESSAGE_LEVELS': {'DEBUG': 10, 'INFO': 20, 'WARNING': 30, 'SUCCESS': 25, 'ERROR': 40}, 'messages': <django.contrib.messages.storage.fallback.FallbackStorage object at 0x7f831d159110>, 'global_message': 'This is a global test message', u'request': <WSGIRequest: GET '/index/'>, 'site_url': 'http://www.newbieol.com'}, {}]"
