2017-01-17 09:27:08,234 [Thread-2:140470041724672] [django.request:182] [base:get_response] [WARNING]- Not Found: /
2017-01-17 09:27:10,976 [Thread-3:140470041724672] [django.request:182] [base:get_response] [WARNING]- Not Found: /favicon.ico
2017-01-17 09:27:56,034 [Thread-17:140470033069824] [django.request:284] [base:handle_uncaught_exception] [ERROR]- Internal Server Error: /admin/myapp/author/
Traceback (most recent call last):
  File "/usr/local/lib/python2.7/dist-packages/Django-1.9.7-py2.7.egg/django/core/handlers/base.py", line 174, in get_response
    response = self.process_exception_by_middleware(e, request)
  File "/usr/local/lib/python2.7/dist-packages/Django-1.9.7-py2.7.egg/django/core/handlers/base.py", line 172, in get_response
    response = response.render()
  File "/usr/local/lib/python2.7/dist-packages/Django-1.9.7-py2.7.egg/django/template/response.py", line 160, in render
    self.content = self.rendered_content
  File "/usr/local/lib/python2.7/dist-packages/Django-1.9.7-py2.7.egg/django/template/response.py", line 137, in rendered_content
    content = template.render(context, self._request)
  File "/usr/local/lib/python2.7/dist-packages/Django-1.9.7-py2.7.egg/django/template/backends/django.py", line 95, in render
    return self.template.render(context)
  File "/usr/local/lib/python2.7/dist-packages/Django-1.9.7-py2.7.egg/django/template/base.py", line 206, in render
    return self._render(context)
  File "/usr/local/lib/python2.7/dist-packages/Django-1.9.7-py2.7.egg/django/template/base.py", line 197, in _render
    return self.nodelist.render(context)
  File "/usr/local/lib/python2.7/dist-packages/Django-1.9.7-py2.7.egg/django/template/base.py", line 992, in render
    bit = node.render_annotated(context)
  File "/usr/local/lib/python2.7/dist-packages/Django-1.9.7-py2.7.egg/django/template/base.py", line 959, in render_annotated
    return self.render(context)
  File "/usr/local/lib/python2.7/dist-packages/Django-1.9.7-py2.7.egg/django/template/loader_tags.py", line 173, in render
    return compiled_parent._render(context)
  File "/usr/local/lib/python2.7/dist-packages/Django-1.9.7-py2.7.egg/django/template/base.py", line 197, in _render
    return self.nodelist.render(context)
  File "/usr/local/lib/python2.7/dist-packages/Django-1.9.7-py2.7.egg/django/template/base.py", line 992, in render
    bit = node.render_annotated(context)
  File "/usr/local/lib/python2.7/dist-packages/Django-1.9.7-py2.7.egg/django/template/base.py", line 959, in render_annotated
    return self.render(context)
  File "/usr/local/lib/python2.7/dist-packages/Django-1.9.7-py2.7.egg/django/template/loader_tags.py", line 173, in render
    return compiled_parent._render(context)
  File "/usr/local/lib/python2.7/dist-packages/Django-1.9.7-py2.7.egg/django/template/base.py", line 197, in _render
    return self.nodelist.render(context)
  File "/usr/local/lib/python2.7/dist-packages/Django-1.9.7-py2.7.egg/django/template/base.py", line 992, in render
    bit = node.render_annotated(context)
  File "/usr/local/lib/python2.7/dist-packages/Django-1.9.7-py2.7.egg/django/template/base.py", line 959, in render_annotated
    return self.render(context)
  File "/usr/local/lib/python2.7/dist-packages/Django-1.9.7-py2.7.egg/django/template/loader_tags.py", line 69, in render
    result = block.nodelist.render(context)
  File "/usr/local/lib/python2.7/dist-packages/Django-1.9.7-py2.7.egg/django/template/base.py", line 992, in render
    bit = node.render_annotated(context)
  File "/usr/local/lib/python2.7/dist-packages/Django-1.9.7-py2.7.egg/django/template/base.py", line 959, in render_annotated
    return self.render(context)
  File "/usr/local/lib/python2.7/dist-packages/Django-1.9.7-py2.7.egg/django/template/loader_tags.py", line 69, in render
    result = block.nodelist.render(context)
  File "/usr/local/lib/python2.7/dist-packages/Django-1.9.7-py2.7.egg/django/template/base.py", line 992, in render
    bit = node.render_annotated(context)
  File "/usr/local/lib/python2.7/dist-packages/Django-1.9.7-py2.7.egg/django/template/base.py", line 959, in render_annotated
    return self.render(context)
  File "/usr/local/lib/python2.7/dist-packages/Django-1.9.7-py2.7.egg/django/template/library.py", line 223, in render
    _dict = self.func(*resolved_args, **resolved_kwargs)
  File "/usr/local/lib/python2.7/dist-packages/Django-1.9.7-py2.7.egg/django/contrib/admin/templatetags/admin_list.py", line 326, in result_list
    'results': list(results(cl))}
  File "/usr/local/lib/python2.7/dist-packages/Django-1.9.7-py2.7.egg/django/contrib/admin/templatetags/admin_list.py", line 302, in results
    yield ResultList(None, items_for_result(cl, res, None))
  File "/usr/local/lib/python2.7/dist-packages/Django-1.9.7-py2.7.egg/django/contrib/admin/templatetags/admin_list.py", line 293, in __init__
    super(ResultList, self).__init__(*items)
  File "/usr/local/lib/python2.7/dist-packages/Django-1.9.7-py2.7.egg/django/contrib/admin/templatetags/admin_list.py", line 202, in items_for_result
    f, attr, value = lookup_field(field_name, result, cl.model_admin)
  File "/usr/local/lib/python2.7/dist-packages/Django-1.9.7-py2.7.egg/django/contrib/admin/utils.py", line 290, in lookup_field
    value = attr()
  File "/usr/local/lib/python2.7/dist-packages/Django-1.9.7-py2.7.egg/django/db/models/base.py", line 474, in __str__
    return force_text(self).encode('utf-8')
  File "/usr/local/lib/python2.7/dist-packages/Django-1.9.7-py2.7.egg/django/utils/encoding.py", line 78, in force_text
    s = six.text_type(s)
  File "/home/linux/django_web/booksite/myapp/models.py", line 28, in __unicode__
    return u"%s %s"%(self.first_name,self,last_name)
NameError: global name 'last_name' is not defined
2017-01-17 09:36:50,997 [Thread-87:139905799808768] [django.request:182] [base:get_response] [WARNING]- Not Found: /
2017-01-17 09:36:51,052 [Thread-88:139905791416064] [django.request:182] [base:get_response] [WARNING]- Not Found: /favicon.ico
2017-01-17 10:08:52,640 [Thread-107:139905766237952] [django.request:182] [base:get_response] [WARNING]- Not Found: /
2017-01-17 10:08:58,327 [Thread-108:139905766237952] [django.request:284] [base:handle_uncaught_exception] [ERROR]- Internal Server Error: /models/
Traceback (most recent call last):
  File "/usr/local/lib/python2.7/dist-packages/Django-1.9.7-py2.7.egg/django/core/handlers/base.py", line 149, in get_response
    response = self.process_exception_by_middleware(e, request)
  File "/usr/local/lib/python2.7/dist-packages/Django-1.9.7-py2.7.egg/django/core/handlers/base.py", line 147, in get_response
    response = wrapped_callback(request, *callback_args, **callback_kwargs)
  File "/home/linux/django_web/booksite/myapp/views.py", line 59, in models_fun
    b = Author.objects.get(id = 1)
  File "/usr/local/lib/python2.7/dist-packages/Django-1.9.7-py2.7.egg/django/db/models/manager.py", line 122, in manager_method
    return getattr(self.get_queryset(), name)(*args, **kwargs)
  File "/usr/local/lib/python2.7/dist-packages/Django-1.9.7-py2.7.egg/django/db/models/query.py", line 387, in get
    self.model._meta.object_name
DoesNotExist: Author matching query does not exist.
2017-01-17 10:12:03,135 [Thread-2:140431750878976] [django.request:284] [base:handle_uncaught_exception] [ERROR]- Internal Server Error: /models/
Traceback (most recent call last):
  File "/usr/local/lib/python2.7/dist-packages/Django-1.9.7-py2.7.egg/django/core/handlers/base.py", line 149, in get_response
    response = self.process_exception_by_middleware(e, request)
  File "/usr/local/lib/python2.7/dist-packages/Django-1.9.7-py2.7.egg/django/core/handlers/base.py", line 147, in get_response
    response = wrapped_callback(request, *callback_args, **callback_kwargs)
  File "/home/linux/django_web/booksite/myapp/views.py", line 65, in models_fun
    return render(request,'models.html',locals())
  File "/usr/local/lib/python2.7/dist-packages/Django-1.9.7-py2.7.egg/django/shortcuts.py", line 67, in render
    template_name, context, request=request, using=using)
  File "/usr/local/lib/python2.7/dist-packages/Django-1.9.7-py2.7.egg/django/template/loader.py", line 97, in render_to_string
    return template.render(context, request)
  File "/usr/local/lib/python2.7/dist-packages/Django-1.9.7-py2.7.egg/django/template/backends/django.py", line 95, in render
    return self.template.render(context)
  File "/usr/local/lib/python2.7/dist-packages/Django-1.9.7-py2.7.egg/django/template/base.py", line 206, in render
    return self._render(context)
  File "/usr/local/lib/python2.7/dist-packages/Django-1.9.7-py2.7.egg/django/template/base.py", line 197, in _render
    return self.nodelist.render(context)
  File "/usr/local/lib/python2.7/dist-packages/Django-1.9.7-py2.7.egg/django/template/base.py", line 992, in render
    bit = node.render_annotated(context)
  File "/usr/local/lib/python2.7/dist-packages/Django-1.9.7-py2.7.egg/django/template/base.py", line 959, in render_annotated
    return self.render(context)
  File "/usr/local/lib/python2.7/dist-packages/Django-1.9.7-py2.7.egg/django/template/defaulttags.py", line 167, in render
    values = list(values)
TypeError: 'Book' object is not iterable
2017-01-17 10:19:34,563 [Thread-4:140250313889536] [django.request:284] [base:handle_uncaught_exception] [ERROR]- Internal Server Error: /models/
Traceback (most recent call last):
  File "/usr/local/lib/python2.7/dist-packages/Django-1.9.7-py2.7.egg/django/core/handlers/base.py", line 149, in get_response
    response = self.process_exception_by_middleware(e, request)
  File "/usr/local/lib/python2.7/dist-packages/Django-1.9.7-py2.7.egg/django/core/handlers/base.py", line 147, in get_response
    response = wrapped_callback(request, *callback_args, **callback_kwargs)
  File "/home/linux/django_web/booksite/myapp/views.py", line 71, in models_fun
    return render(request,'models.html',locals())
  File "/usr/local/lib/python2.7/dist-packages/Django-1.9.7-py2.7.egg/django/shortcuts.py", line 67, in render
    template_name, context, request=request, using=using)
  File "/usr/local/lib/python2.7/dist-packages/Django-1.9.7-py2.7.egg/django/template/loader.py", line 96, in render_to_string
    template = get_template(template_name, using=using)
  File "/usr/local/lib/python2.7/dist-packages/Django-1.9.7-py2.7.egg/django/template/loader.py", line 32, in get_template
    return engine.get_template(template_name, dirs)
  File "/usr/local/lib/python2.7/dist-packages/Django-1.9.7-py2.7.egg/django/template/backends/django.py", line 40, in get_template
    return Template(self.engine.get_template(template_name, dirs), self)
  File "/usr/local/lib/python2.7/dist-packages/Django-1.9.7-py2.7.egg/django/template/engine.py", line 190, in get_template
    template, origin = self.find_template(template_name, dirs)
  File "/usr/local/lib/python2.7/dist-packages/Django-1.9.7-py2.7.egg/django/template/engine.py", line 157, in find_template
    name, template_dirs=dirs, skip=skip,
  File "/usr/local/lib/python2.7/dist-packages/Django-1.9.7-py2.7.egg/django/template/loaders/base.py", line 46, in get_template
    contents, origin, origin.template_name, self.engine,
  File "/usr/local/lib/python2.7/dist-packages/Django-1.9.7-py2.7.egg/django/template/base.py", line 189, in __init__
    self.nodelist = self.compile_nodelist()
  File "/usr/local/lib/python2.7/dist-packages/Django-1.9.7-py2.7.egg/django/template/base.py", line 231, in compile_nodelist
    return parser.parse()
  File "/usr/local/lib/python2.7/dist-packages/Django-1.9.7-py2.7.egg/django/template/base.py", line 487, in parse
    raise self.error(token, e)
TemplateSyntaxError: Could not parse the remainder: '%for l in publisher1.book_set.all%' from '%for l in publisher1.book_set.all%'
2017-01-17 11:13:17,393 [Thread-2:140500474189568] [django.request:284] [base:handle_uncaught_exception] [ERROR]- Internal Server Error: /models/
Traceback (most recent call last):
  File "/usr/local/lib/python2.7/dist-packages/Django-1.9.7-py2.7.egg/django/core/handlers/base.py", line 149, in get_response
    response = self.process_exception_by_middleware(e, request)
  File "/usr/local/lib/python2.7/dist-packages/Django-1.9.7-py2.7.egg/django/core/handlers/base.py", line 147, in get_response
    response = wrapped_callback(request, *callback_args, **callback_kwargs)
  File "/home/linux/django_web/booksite/myapp/views.py", line 72, in models_fun
    count = book1.title_count("Html5")
AttributeError: 'Book' object has no attribute 'title_count'
2017-01-17 11:15:05,408 [Thread-2:140719629264640] [django.request:284] [base:handle_uncaught_exception] [ERROR]- Internal Server Error: /models/
Traceback (most recent call last):
  File "/usr/local/lib/python2.7/dist-packages/Django-1.9.7-py2.7.egg/django/core/handlers/base.py", line 149, in get_response
    response = self.process_exception_by_middleware(e, request)
  File "/usr/local/lib/python2.7/dist-packages/Django-1.9.7-py2.7.egg/django/core/handlers/base.py", line 147, in get_response
    response = wrapped_callback(request, *callback_args, **callback_kwargs)
  File "/home/linux/django_web/booksite/myapp/views.py", line 72, in models_fun
    count = book1.title_count("Html5")
AttributeError: 'Book' object has no attribute 'title_count'
2017-01-17 11:20:52,618 [Thread-2:140083666773760] [django.request:284] [base:handle_uncaught_exception] [ERROR]- Internal Server Error: /models/
Traceback (most recent call last):
  File "/usr/local/lib/python2.7/dist-packages/Django-1.9.7-py2.7.egg/django/core/handlers/base.py", line 149, in get_response
    response = self.process_exception_by_middleware(e, request)
  File "/usr/local/lib/python2.7/dist-packages/Django-1.9.7-py2.7.egg/django/core/handlers/base.py", line 147, in get_response
    response = wrapped_callback(request, *callback_args, **callback_kwargs)
  File "/home/linux/django_web/booksite/myapp/views.py", line 55, in models_fun
    book = Book.objects.all()
AttributeError: type object 'Book' has no attribute 'objects'
2017-01-17 11:21:11,338 [Thread-2:140510899205888] [django.request:284] [base:handle_uncaught_exception] [ERROR]- Internal Server Error: /models/
Traceback (most recent call last):
  File "/usr/local/lib/python2.7/dist-packages/Django-1.9.7-py2.7.egg/django/core/handlers/base.py", line 149, in get_response
    response = self.process_exception_by_middleware(e, request)
  File "/usr/local/lib/python2.7/dist-packages/Django-1.9.7-py2.7.egg/django/core/handlers/base.py", line 147, in get_response
    response = wrapped_callback(request, *callback_args, **callback_kwargs)
  File "/home/linux/django_web/booksite/myapp/views.py", line 55, in models_fun
    book = Book.objects.all()
AttributeError: type object 'Book' has no attribute 'objects'
2017-01-17 11:22:28,122 [Thread-2:140241296152320] [django.request:284] [base:handle_uncaught_exception] [ERROR]- Internal Server Error: /models/
Traceback (most recent call last):
  File "/usr/local/lib/python2.7/dist-packages/Django-1.9.7-py2.7.egg/django/core/handlers/base.py", line 149, in get_response
    response = self.process_exception_by_middleware(e, request)
  File "/usr/local/lib/python2.7/dist-packages/Django-1.9.7-py2.7.egg/django/core/handlers/base.py", line 147, in get_response
    response = wrapped_callback(request, *callback_args, **callback_kwargs)
  File "/home/linux/django_web/booksite/myapp/views.py", line 72, in models_fun
    count = Book.myobjects.title_count('Html5')
AttributeError: type object 'Book' has no attribute 'myobjects'
2017-01-17 11:56:27,220 [Thread-15:139880616474368] [django.request:284] [base:handle_uncaught_exception] [ERROR]- Internal Server Error: /models/
Traceback (most recent call last):
  File "/usr/local/lib/python2.7/dist-packages/Django-1.9.7-py2.7.egg/django/core/handlers/base.py", line 149, in get_response
    response = self.process_exception_by_middleware(e, request)
  File "/usr/local/lib/python2.7/dist-packages/Django-1.9.7-py2.7.egg/django/core/handlers/base.py", line 147, in get_response
    response = wrapped_callback(request, *callback_args, **callback_kwargs)
  File "/home/linux/django_web/booksite/myapp/views.py", line 59, in models_fun
    b = Author.objects.get(id = 2)
  File "/usr/local/lib/python2.7/dist-packages/Django-1.9.7-py2.7.egg/django/db/models/manager.py", line 122, in manager_method
    return getattr(self.get_queryset(), name)(*args, **kwargs)
  File "/usr/local/lib/python2.7/dist-packages/Django-1.9.7-py2.7.egg/django/db/models/query.py", line 387, in get
    self.model._meta.object_name
DoesNotExist: Author matching query does not exist.
2017-01-17 15:24:28,076 [Thread-10:140370057619200] [django.request:182] [base:get_response] [WARNING]- Not Found: /favicon.ico
2017-01-17 16:11:32,774 [Thread-3:139880415352576] [django.request:182] [base:get_response] [WARNING]- Not Found: /reg
2017-01-17 16:12:30,259 [Thread-20:139880398305024] [django.request:284] [base:handle_uncaught_exception] [ERROR]- Internal Server Error: /form/reg/
Traceback (most recent call last):
  File "/usr/local/lib/python2.7/dist-packages/Django-1.9.7-py2.7.egg/django/core/handlers/base.py", line 149, in get_response
    response = self.process_exception_by_middleware(e, request)
  File "/usr/local/lib/python2.7/dist-packages/Django-1.9.7-py2.7.egg/django/core/handlers/base.py", line 147, in get_response
    response = wrapped_callback(request, *callback_args, **callback_kwargs)
  File "/home/linux/django_web/booksite/formapp/views.py", line 91, in reg
    logger.error(e)
NameError: global name 'logger' is not defined
2017-01-18 09:09:24,113 [Thread-2:140087404001024] [django.request:182] [base:get_response] [WARNING]- Not Found: /
2017-01-18 09:09:24,208 [Thread-3:140087395608320] [django.request:182] [base:get_response] [WARNING]- Not Found: /favicon.ico
2017-01-18 09:39:11,096 [Thread-5:140029318817536] [django.request:284] [base:handle_uncaught_exception] [ERROR]- Internal Server Error: /form/login/
Traceback (most recent call last):
  File "/usr/local/lib/python2.7/dist-packages/Django-1.9.7-py2.7.egg/django/core/handlers/base.py", line 149, in get_response
    response = self.process_exception_by_middleware(e, request)
  File "/usr/local/lib/python2.7/dist-packages/Django-1.9.7-py2.7.egg/django/core/handlers/base.py", line 147, in get_response
    response = wrapped_callback(request, *callback_args, **callback_kwargs)
  File "/home/linux/django_web/booksite/formapp/views.py", line 103, in login
    user = auth.authenticate(username=username,password=password)
NameError: global name 'auth' is not defined
2017-01-18 09:42:55,968 [Thread-6:140343139362560] [django.request:182] [base:get_response] [WARNING]- Not Found: /
2017-01-18 09:43:28,194 [Thread-20:140343139362560] [django.request:103] [csrf:_reject] [WARNING]- Forbidden (CSRF token missing or incorrect.): /form/login/
2017-01-18 10:12:46,709 [Thread-5:140240169789184] [django.request:182] [base:get_response] [WARNING]- Not Found: /form/thanks/
2017-01-18 10:12:55,441 [Thread-7:140240169789184] [django.request:182] [base:get_response] [WARNING]- Not Found: /form/thanks/
2017-01-18 10:13:14,461 [Thread-8:140240169789184] [django.request:182] [base:get_response] [WARNING]- Not Found: /form/thanks/
